import React, { Component, ErrorInfo, ReactNode } from 'react';
import { AlertTriangle, RefreshCw } from 'lucide-react';
import { Button } from '@/components/ui/button';
import { Card, CardContent, CardHeader, CardTitle } from '@/components/ui/card';

interface Props {
  children: ReactNode;
  fallback?: ReactNode;
}

interface State {
  hasError: boolean;
  error?: Error;
  errorInfo?: ErrorInfo;
}

export class ErrorBoundary extends Component<Props, State> {
  constructor(props: Props) {
    super(props);
    this.state = { hasError: false };
  }

  static getDerivedStateFromError(error: Error): State {
    // Update state so the next render will show the fallback UI
    return { hasError: true, error };
  }

  componentDidCatch(error: Error, errorInfo: ErrorInfo) {
    // Log the error to console and any error reporting service
    console.error('ErrorBoundary caught an error:', error, errorInfo);
    
    // You can also log the error to an error reporting service here
    // Example: Sentry.captureException(error, { extra: errorInfo });
    
    this.setState({ error, errorInfo });
  }

  handleRetry = () => {
    this.setState({ hasError: false, error: undefined, errorInfo: undefined });
  };

  handleReload = () => {
    window.location.reload();
  };

  render() {
    if (this.state.hasError) {
      // Custom fallback UI
      if (this.props.fallback) {
        return this.props.fallback;
      }

      // Default error UI
      return (
        <div className="min-h-screen bg-background flex items-center justify-center p-4">
          <Card className="w-full max-w-md">
            <CardHeader className="text-center">
              <div className="mx-auto mb-4 flex h-12 w-12 items-center justify-center rounded-full bg-destructive/10">
                <AlertTriangle className="h-6 w-6 text-destructive" />
              </div>
              <CardTitle className="text-xl">Something went wrong</CardTitle>
            </CardHeader>
            <CardContent className="space-y-4">
              <p className="text-center text-muted-foreground">
                We encountered an unexpected error. Please try again or reload the page.
              </p>
              
              {process.env.NODE_ENV === 'development' && this.state.error && (
                <details className="text-xs">
                  <summary className="cursor-pointer text-muted-foreground">
                    Error details (development only)
                  </summary>
                  <pre className="mt-2 p-2 bg-muted rounded text-xs overflow-auto">
                    {this.state.error.toString()}
                    {this.state.errorInfo?.componentStack}
                  </pre>
                </details>
              )}
              
              <div className="flex space-x-2">
                <Button 
                  variant="outline" 
                  onClick={this.handleRetry}
                  className="flex-1"
                >
                  <RefreshCw className="h-4 w-4 mr-2" />
                  Try Again
                </Button>
                <Button 
                  onClick={this.handleReload}
                  className="flex-1"
                >
                  Reload Page
                </Button>
              </div>
            </CardContent>
          </Card>
        </div>
      );
    }

    return this.props.children;
  }
}

// Higher-order component to wrap components with error boundary
export function withErrorBoundary<P extends object>(
  Component: React.ComponentType<P>,
  fallback?: ReactNode
) {
  return function WithErrorBoundary(props: P) {
    return (
      <ErrorBoundary fallback={fallback}>
        <Component {...props} />
      </ErrorBoundary>
    );
  };
}

// Hook to handle async errors
export function useAsyncError() {
  const [, setError] = React.useState();
  return React.useCallback(
    (e: Error) => {
      setError(() => {
        throw e;
      });
    },
    []
  );
} 